Workbook

Sheet Reservas
A1: Nome | B1: Turma | C1: Data | D1: Horário de retirada | E1: Horário de devolução | F1: Atividade | G1: Quantidade solicitada | H1: Retirada | I1: Quantidade devolvida | J1: Disponibilidade atual | K1: {=XLOOKUP(TODAY(),Estoque!A:A,Estoque!C:C)} -> 30
A2: Leonardo | B2: WU80 | C2: 46002 | D2: 0.65625 | F2: Avaliação prática - paquímetro | G2: 11 | H2: 11
A3: Rosandro | B3: WM77 | C3: 45993 | D3: 0.3125 | E3: 0.58888889 | F3: Prática em laboratório | G3: 6 | I3: 6
A4: Mariel | B4: MQ78 | C4: 45993 | D4: 0.51736111 | E4: 0.60416667 | F4: Pesquisa experimentos | G4: 10 | I4: 10
A5: Ricardo | B5: MT75 | C5: 45993 | D5: 0.52083333 | E5: 0.6875 | F5: Pesquisa experimentos | G5: 7 | I5: 7
A6: João Paulo | B6: ME | C6: 45993 | D6: 0.52083333 | E6: 0.6875 | F6: Leitura de manual e Parametros CFW | G6: 10 | I6: 10
A7: Vinicius Siqueira | B7: ME79 | C7: 45993 | D7: 0.65555556 | E7: 0.70833333 | F7: Atividades em sala de aula | G7: 12 | I7: 12
A8: Girleida Rocha | B8: MT78 | C8: 45994 | D8: 0.31944444 | E8: 0.45833333 | F8: Atividades em sala de aula | G8: 4 | I8: 4
A9: Vagner Vicentini | B9: OPME | C9: 45994 | D9: 0.61458333 | E9: 0.73958333 | F9: Atividade em sala de aula | G9: 12 | H9: ok | I9: 12
A10: Jean C silva | B10: WU79 | C10: 45994 | D10: 0.75 | E10: 0.91666667 | F10: Atividade CNC | G10: 6 | H10: ok
A11: William | B11: MM77 | C11: 45994 | D11: 0.75 | E11: 0.875 | F11: Atividade no Laboratório | G11: 12 | H11: ok
A12: Jairo | B12: ME 79 | C12: 45994 | D12: 0.625 | E12: 0.89583333 | F12: Atividade em sala de aula | G12: 10 | H12: ok
A13: Jailson | B13: MM76 | C13: 45995 | D13: 0.3125 | F13: Atividade no Laboratório | G13: 10 | H13: ok | I13: ok
A14: Karina | B14: MQ78 | C14: 45995 | D14: 0.43402778 | E14: 0.45833333 | F14: Pesquisa | G14: 1 | H14: ok | I14: ok
A15: Girleida Rocha | B15: MT78 | C15: 45995 | D15: 0.51041667 | E15: 0.59375 | F15: Atividade: Elaboração de Trabalho | G15: 2 | H15: ok | I15: ok
A16: Mariel | B16: MQ78 | C16: 45995 | D16: 0.51875 | E16: 0.60416667 | F16: Pesquisa experimentos | G16: 10 | H16: ok | I16: 10
A17: Ricardo | B17: MT 75 | C17: 45995 | D17: 0.52083333 | E17: 0.6875 | F17: Atividade | G17: 9 | H17: ok | I17: ok
A18: Girleida Rocha | B18: WU79 | C18: 45995 | D18: 0.61458333 | E18: 0.71527778 | G18: 20 | I18: ok
A19: Jairo | B19: ME 79 | C19: 45995 | D19: 0.61458333 | E19: 0.90625 | F19: Atividade Pratica | G19: 1 | H19: ok | I19: ok
A20: Lucas | B20: MI 80 | C20: 45995 | D20: 0.75 | E20: 0.90625 | F20: Avaliação banca (apresentação) | G20: 4 | H20: ok | I20: ok
A21: Lucas Santos | B21: MA 77 | C21: 45996 | D21: 0.33333333 | E21: 0.60416667 | F21: Pesquisa Aplicada | G21: 1 | H21: ok | I21: 1
A22: João | B22: Mt 76 | C22: 45996 | D22: 0.35972222 | E22: 0.45833333 | F22: Pesquisa Aplicada | G22: 1 | H22: ok | I22: 1
A23: Augusto | B23: MA 78 | C23: 45996 | D23: 0.61805556 | E23: 0.70833333 | F23: Pesquisa Aplicada | G23: 24 | H23: ok
A24: jairo | B24: ME 78 | C24: 45996 | D24: 0.625 | E24: 0.625 | F24: pesquisa | G24: 12 | H24: ok
A25: William | B25: MM77 | C25: 45996 | D25: 0.63888889 | E25: 0.70833333 | F25: Atividade Laboratório | G25: 6
A26: Douglas | B26: MT 75 | C26: 45999 | D26: 0.31805556 | E26: 0.46180556 | F26: Atividade labiratório | G26: 17 | H26: ok | I26: 17
A27: João Paulo | B27: ME 76 | C27: 45999 | D27: 0.32291667 | E27: 0.45833333 | F27: Consulta de Manual | G27: 10 | H27: ok | I27: 10
A28: Mariel | B28: MQ78 | C28: 45999 | D28: 0.5 | E28: 0.60416667 | F28: Resposta a formulário | G28: 20 | H28: ok | I28: 20
A29: Rosandro | B29: WM77 | C29: 45999 | D29: 0.40625 | E29: 0.60416667 | F29: Pesquisa | G29: 11 | H29: ok | I29: 11
A30: Jailson | B30: MM 76 | C30: 45999 | D30: 0.52083333 | F30: Atividade labiratório | G30: 11 | I30: 11
A31: José | B31: MT 75 | C31: 45999 | D31: 0.54166667 | F31: VR | G31: 7 | H31: ok | I31: 7
A32: Augusto | C32: 45999 | D32: 0.77083333 | E32: 0.90277778 | F32: Apresentação | G32: 15 | H32: ok | I32: 15
A33: Jailson | B33: MM 76 | C33: 46000 | F33: Atividade labiratório | G33: 10 | H33: ok | I33: 10
A34: João Paulo | B34: WME77 | C34: 46000 | D34: 0.32291667 | E34: 0.6875 | F34: Consulta de Manual | G34: 10 | H34: ok | I34: 10
A35: Mariel | B35: MQ78 | C35: 46000 | D35: 0.52777778 | E35: 0.60416667 | F35: Pesquisa | G35: 6 | H35: ok | I35: 6
A36: Jairo | B36: MF 78 | C36: 46000 | D36: 0.61111111 | E36: 0.90625 | F36: Atividades | G36: 1 | H36: ok | I36: 1
A37: Leonardo | B37: WME78 | C37: 46000 | D37: 0.64236111 | F37: Workshop | G37: 10 | I37: 10
A38: Ramon | B38: MM 76 | C38: 46000 | D38: 0.76388889 | G38: 5 | H38: ok | I38: 5
A39: Carlos | B39: MI78 | C39: 46000 | D39: 0.77777778 | F39: sniffer rede sem fio | G39: 5 | H39: ok | I39: 5
A40: Karina | B40: MQ78 | C40: 46001 | D40: 0.5 | E40: 0.60416667 | F40: Consulta de exercícios | G40: 11 | H40: ok
...

Sheet Estoque
A1: data | B1: quantidade reservada | C1: disponíveis | D1: Devolvido
A2: 45992 | B2: =SUMIF(Reservas!C:C,A2,Reservas!G:G) -> 0 | C2: =(70-B2)+D2 -> 70 | D2: =SUMIF(Reservas!C:C,A2,Reservas!I:I) -> 0
A3: 45993 | B3: =SUMIF(Reservas!C:C,A3,Reservas!G:G) -> 45 | C3: =(70-B3)+D3 -> 70 | D3: =SUMIF(Reservas!C:C,A3,Reservas!I:I) -> 45
A4: 45994 | B4: =SUMIF(Reservas!C:C,A4,Reservas!G:G) -> 44 | C4: =(70-B4)+D4 -> 42 | D4: =SUMIF(Reservas!C:C,A4,Reservas!I:I) -> 16
A5: 45995 | B5: =SUMIF(Reservas!C:C,A5,Reservas!G:G) -> 57 | C5: =(70-B5)+D5 -> 23 | D5: =SUMIF(Reservas!C:C,A5,Reservas!I:I) -> 10
A6: 45996 | B6: =SUMIF(Reservas!C:C,A6,Reservas!G:G) -> 44 | C6: =(70-B6)+D6 -> 28 | D6: =SUMIF(Reservas!C:C,A6,Reservas!I:I) -> 2
A7: 45997 | B7: =SUMIF(Reservas!C:C,A7,Reservas!G:G) -> 0 | C7: =(70-B7)+D7 -> 70 | D7: =SUMIF(Reservas!C:C,A7,Reservas!I:I) -> 0
A8: 45998 | B8: =SUMIF(Reservas!C:C,A8,Reservas!G:G) -> 0 | C8: =(70-B8)+D8 -> 70 | D8: =SUMIF(Reservas!C:C,A8,Reservas!I:I) -> 0
A9: 45999 | B9: =SUMIF(Reservas!C:C,A9,Reservas!G:G) -> 91 | C9: =(70-B9)+D9 -> 70 | D9: =SUMIF(Reservas!C:C,A9,Reservas!I:I) -> 91
A10: 46000 | B10: =SUMIF(Reservas!C:C,A10,Reservas!G:G) -> 47 | C10: =(70-B10)+D10 -> 70 | D10: =SUMIF(Reservas!C:C,A10,Reservas!I:I) -> 47
A11: 46001 | B11: =SUMIF(Reservas!C:C,A11,Reservas!G:G) -> 89 | C11: =(70-B11)+D11 -> -17 | D11: =SUMIF(Reservas!C:C,A11,Reservas!I:I) -> 2
A12: 46002 | B12: =SUMIF(Reservas!C:C,A12,Reservas!G:G) -> 57 | C12: =(70-B12)+D12 -> 25 | D12: =SUMIF(Reservas!C:C,A12,Reservas!I:I) -> 12
A13: 46003 | B13: =SUMIF(Reservas!C:C,A13,Reservas!G:G) -> 14 | C13: =(70-B13)+D13 -> 56 | D13: =SUMIF(Reservas!C:C,A13,Reservas!I:I) -> 0
... A136: 46126 | B136: =SUMIF(Reservas!C:C,A136,Reservas!G:G) -> 69 | C136: =(70-B136)+D136 -> 1 | D136: =SUMIF(Reservas!C:C,A136,Reservas!I:I) -> 0
A137: 46127 | B137: =SUMIF(Reservas!C:C,A137,Reservas!G:G) -> 26 | C137: =(50-B137)+D137 -> 24 | D137: =SUMIF(Reservas!C:C,A137,Reservas!I:I) -> 0
A138: 46128 | B138: =SUMIF(Reservas!C:C,A138,Reservas!G:G) -> 35 | C138: =(50-B138)+D138 -> 15 | D138: =SUMIF(Reservas!C:C,A138,Reservas!I:I) -> 0
A139: 46129 | B139: =SUMIF(Reservas!C:C,A139,Reservas!G:G) -> 50 | C139: =(50-B139)+D139 -> 0 | D139: =SUMIF(Reservas!C:C,A139,Reservas!I:I) -> 0
A140: 46130 | B140: =SUMIF(Reservas!C:C,A140,Reservas!G:G) -> 0 | C140: =(50-B140)+D140 -> 50 | D140: =SUMIF(Reservas!C:C,A140,Reservas!I:I) -> 0
A141: 46131 | B141: =SUMIF(Reservas!C:C,A141,Reservas!G:G) -> 0 | C141: =(50-B141)+D141 -> 50 | D141: =SUMIF(Reservas!C:C,A141,Reservas!I:I) -> 0
A142: 46132 | B142: =SUMIF(Reservas!C:C,A142,Reservas!G:G) -> 0 | C142: =(50-B142)+D142 -> 50 | D142: =SUMIF(Reservas!C:C,A142,Reservas!I:I) -> 0
A143: 46133 | B143: =SUMIF(Reservas!C:C,A143,Reservas!G:G) -> 0 | C143: =(50-B143)+D143 -> 50 | D143: =SUMIF(Reservas!C:C,A143,Reservas!I:I) -> 0
A144: 46134 | B144: =SUMIF(Reservas!C:C,A144,Reservas!G:G) -> 30 | C144: =(50-B144)+D144 -> 20 | D144: =SUMIF(Reservas!C:C,A144,Reservas!I:I) -> 0
A145: 46135 | B145: =SUMIF(Reservas!C:C,A145,Reservas!G:G) -> 24 | C145: =(50-B145)+D145 -> 26 | D145: =SUMIF(Reservas!C:C,A145,Reservas!I:I) -> 0
A146: 46136 | B146: =SUMIF(Reservas!C:C,A146,Reservas!G:G) -> 32 | C146: =(50-B146)+D146 -> 18 | D146: =SUMIF(Reservas!C:C,A146,Reservas!I:I) -> 0
A147: 46137 | B147: =SUMIF(Reservas!C:C,A147,Reservas!G:G) -> 0 | C147: =(50-B147)+D147 -> 50 | D147: =SUMIF(Reservas!C:C,A147,Reservas!I:I) -> 0
A148: 46138 | B148: =SUMIF(Reservas!C:C,A148,Reservas!G:G) -> 0 | C148: =(50-B148)+D148 -> 50 | D148: =SUMIF(Reservas!C:C,A148,Reservas!I:I) -> 0
... A183: 46173 | B183: =SUMIF(Reservas!C:C,A183,Reservas!G:G) -> 0 | C183: =(50-B183)+D183 -> 50 | D183: =SUMIF(Reservas!C:C,A183,Reservas!I:I) -> 0
A184: 46174 | B184: =SUMIF(Reservas!C:C,A184,Reservas!G:G) -> 34 | C184: =(48-B184)+D184 -> 24 | D184: =SUMIF(Reservas!C:C,A184,Reservas!I:I) -> 10
A185: 46175 | B185: =SUMIF(Reservas!C:C,A185,Reservas!G:G) -> 67 | C185: =(48-B185)+D185 -> -9 | D185: =SUMIF(Reservas!C:C,A185,Reservas!I:I) -> 10
A186: 46176 | B186: =SUMIF(Reservas!C:C,A186,Reservas!G:G) -> 49 | C186: =(48-B186)+D186 -> -1 | D186: =SUMIF(Reservas!C:C,A186,Reservas!I:I) -> 0
A187: 46177 | B187: =SUMIF(Reservas!C:C,A187,Reservas!G:G) -> 0 | C187: =(48-B187)+D187 -> 48 | D187: =SUMIF(Reservas!C:C,A187,Reservas!I:I) -> 0
A188: 46178 | B188: =SUMIF(Reservas!C:C,A188,Reservas!G:G) -> 0 | C188: =(48-B188)+D188 -> 48 | D188: =SUMIF(Reservas!C:C,A188,Reservas!I:I) -> 0
A189: 46179 | B189: =SUMIF(Reservas!C:C,A189,Reservas!G:G) -> 0 | C189: =(48-B189)+D189 -> 48 | D189: =SUMIF(Reservas!C:C,A189,Reservas!I:I) -> 0
A190: 46180 | B190: =SUMIF(Reservas!C:C,A190,Reservas!G:G) -> 0 | C190: =(48-B190)+D190 -> 48 | D190: =SUMIF(Reservas!C:C,A190,Reservas!I:I) -> 0
A191: 46181 | B191: =SUMIF(Reservas!C:C,A191,Reservas!G:G) -> 72 | C191: =(48-B191)+D191 -> 14 | D191: =SUMIF(Reservas!C:C,A191,Reservas!I:I) -> 38
A192: 46182 | B192: =SUMIF(Reservas!C:C,A192,Reservas!G:G) -> 60 | C192: =(48-B192)+D192 -> -12 | D192: =SUMIF(Reservas!C:C,A192,Reservas!I:I) -> 0
A193: 46183 | B193: =SUMIF(Reservas!C:C,A193,Reservas!G:G) -> 12 | C193: =(48-B193)+D193 -> 36 | D193: =SUMIF(Reservas!C:C,A193,Reservas!I:I) -> 0
A194: 46184 | B194: =SUMIF(Reservas!C:C,A194,Reservas!G:G) -> 40 | C194: =(48-B194)+D194 -> 8 | D194: =SUMIF(Reservas!C:C,A194,Reservas!I:I) -> 0
A195: 46185 | B195: =SUMIF(Reservas!C:C,A195,Reservas!G:G) -> 27 | C195: =(48-B195)+D195 -> 21 | D195: =SUMIF(Reservas!C:C,A195,Reservas!I:I) -> 0
... A762: 46752 | B762: =SUMIF(Reservas!C:C,A762,Reservas!G:G) -> 0 | C762: =(48-B762)+D762 -> 48 | D762: =SUMIF(Reservas!C:C,A762,Reservas!I:I) -> 0
